Workbook

Sheet Monthly Statistics
B3: Type of Incident | E3: January | F3: February | G3: March | H3: April | I3: May | J3: June | K3: July | L3: August | M3: September | N3: October | O3: November | P3: December | Q3: Total | R3: Total by Classification
B4: LTA-F - Struck by Falling Rock | Q4: =SUM(E4:P4) -> 0 | R4: =SUM(Q4) -> 0
B5: LTA-NF - Struck by Falling Rock | Q5: =SUM(E5:P5) -> 0 | R5: =SUM(Q5:Q8) -> 0
B6: LTA-NF - Caught in Between | Q6: =SUM(E6:P6) -> 0
B7: LTA-NF - Struck by Object | Q7: =SUM(E7:P7) -> 0
B8: LTA-NF - Caught On | Q8: =SUM(E8:P8) -> 0
B9: FAC - Struck by Falling Rock | Q9: =SUM(E9:P9) -> 0 | R9: =SUM(Q9:Q18) -> 0
B10: FAC - Struck by Object | Q10: =SUM(E10:P10) -> 0
B11: FAC - Struck Against | Q11: =SUM(E11:P11) -> 0
B12: FAC - Caught in Between | Q12: =SUM(E12:P12) -> 0
B13: FAC - Punctured | Q13: =SUM(E13:P13) -> 0
B14: FAC - Contact with Smoke | Q14: =SUM(E14:P14) -> 0
B15: FAC - Contact with Electricity | Q15: =SUM(E15:P15) -> 0
B16: FAC - Contact with Chemical | Q16: =SUM(E16:P16) -> 0
B17: FAC - Contact with Object | Q17: =SUM(E17:P17) -> 0
B18: FAC - Fall on Same Level | Q18: =SUM(E18:P18) -> 0
B19: NM - Struck by Falling Rock | Q19: =SUM(E19:P19) -> 0 | R19: =SUM(Q19:Q20) -> 0
B20: NM - Fall on Lower Level | Q20: =SUM(E20:P20) -> 0
B21: Occupational Illness / Pain | Q21: =SUM(E21:P21) -> 0 | R21: =SUM(Q21) -> 0
B22: Property Damage - Fire | Q22: =SUM(E22:P22) -> 0 | R22: =SUM(Q22:Q25) -> 0
B23: Property Damage - NM | Q23: =SUM(E23:P23) -> 0
B24: Property Damage - Struck by Object | Q24: =SUM(E24:P24) -> 0
B25: Property Damage | Q25: =SUM(E25:P25) -> 0
B26: TOTAL | E26: =SUM(E4:E25) -> 0 | F26: =SUM(F4:F25) -> 0 | G26: =SUM(G4:G25) -> 0 | H26: =SUM(H4:H25) -> 0 | I26: =SUM(I4:I25) -> 0 | J26: =SUM(J4:J25) -> 0 | K26: =SUM(K4:K25) -> 0 | L26: =SUM(L4:L25) -> 0 | ... R26: =SUM(R4:R25) -> 0
B30: Occupation / Designation / Property | E30: January | F30: February | G30: March | H30: April | I30: May | J30: June | K30: July | L30: August | M30: September | N30: October | O30: November | P30: December | Q30: Total | R30: Total by Classification
B31: Assistant Miner | Q31: =SUM(E31:P31) -> 0 | R31: =SUM(Q31:Q52) -> 0
B32: Lead Miner | Q32: =SUM(E32:P32) -> 0
B33: Drill Trainee | Q33: =SUM(E33:P33) -> 0
B34: Drill Helper / Assistant Driller | Q34: =SUM(E34:P34) -> 0
B35: Track Man | Q35: =SUM(E35:P35) -> 0
B36: UG Patrol | Q36: =SUM(E36:P36) -> 0
B37: Geologist | Q37: =SUM(E37:P37) -> 0
B38: Geologic Aide | Q38: =SUM(E38:P38) -> 0
B39: Rock Mechanics Aide | Q39: =SUM(E39:P39) -> 0
B40: Geotech & Magsus Aide | Q40: =SUM(E40:P40) -> 0
B41: UG Sampler | Q41: =SUM(E41:P41) -> 0
B42: Mine Planning Engr. | Q42: =SUM(E42:P42) -> 0
B43: Section Head | Q43: =SUM(E43:P43) -> 0
... B52: Control Room Tender | Q52: =SUM(E52:P52) -> 0
B53: Lime Tender | Q53: =SUM(E53:P53) -> 0 | R53: =SUM(Q53:Q68) -> 0
...

Sheet Compliation
A1: Type of Incident | C1: January | J1: February | Q1: March | X1: April | AE1: May | AL1: June | AS1: July | AZ1: August | BG1: September | BN1: October | BU1: November | CB1: December | CI1: Total | CJ1: % Distribution
C2: LTA-F | D2: LTA-NF | E2: NLTA | F2: FAC | G2: NM | H2: OI | I2: PD | J2: LTA-F | K2: LTA-NF | L2: NLTA | M2: FAC | N2: NM | O2: OI | P2: PD | Q2: LTA-F | R2: LTA-NF | S2: NLTA | T2: FAC | U2: NM | V2: OI | W2: PD | X2: LTA-F | Y2: LTA-NF | Z2: NLTA | AA2: FAC | AB2: NM | AC2: OI | AD2: PD | AE2: LTA-F | AF2: LTA-NF | AG2: NLTA | AH2: FAC | AI2: NM | AJ2: OI | AK2: PD | AL2: LTA-F | AM2: LTA-NF | AN2: NLTA | AO2: FAC | AP2: NM | AQ2: OI | AR2: PD | AS2: LTA-F | AT2: LTA-NF | AU2: NLTA | AV2: FAC | AW2: NM | AX2: OI | AY2: PD | AZ2: LTA-F | BA2: LTA-NF | BB2: NLTA | BC2: FAC | BD2: NM | BE2: OI | BF2: PD | BG2: LTA-F | BH2: LTA-NF | BI2: NLTA | BJ2: FAC | BK2: NM | BL2: OI | BM2: PD | BN2: LTA-F | BO2: LTA-NF | BP2: NLTA | BQ2: FAC | BR2: NM | BS2: OI | BT2: PD | BU2: LTA-F | BV2: LTA-NF | BW2: NLTA | BX2: FAC | BY2: NM | BZ2: OI | CA2: PD | CB2: LTA-F | CC2: LTA-NF | CD2: NLTA | CE2: FAC | CF2: NM | CG2: OI | CH2: PD
A3: Struck by Falling Rock | F3: 1 | M3: 1 | T3: 1 | AA3: 2 | AF3: 1 | AS3: 1 | AT3: 2 | AW3: 1 | BA3: 1 | BF3: 1 | BH3: 1 | BJ3: 1 | BK3: 1 | BQ3: 2 | BV3: 1 | BX3: 2 | CI3: =SUM(C3:CH3) -> 20 | CJ3: {=_xlfn.IFS(CI3=0,0,CI3>=1,CI3/CI25)} -> 0.2173913
A4: Struck Against | AO4: 1 | AV4: 1 | BJ4: 1 | BQ4: 1 | BX4: 3 | CI4: =SUM(C4:CH4) -> 7 | CJ4: {=_xlfn.IFS(CI4=0,0,CI4>=1,CI4/CI25)} -> 0.076086957
A5: Struck by object | M5: 1 | T5: 1 | AA5: 1 | AM5: 1 | AV5: 2 | BA5: 1 | BC5: 2 | BH5: 1 | BQ5: 2 | BT5: 1 | BX5: 1 | CI5: =SUM(C5:CH5) -> 14 | CJ5: {=_xlfn.IFS(CI5=0,0,CI5>=1,CI5/CI25)} -> 0.15217391
A6: Caught in between | F6: 4 | K6: 1 | T6: 1 | AO6: 2 | AV6: 3 | BC6: 2 | BX6: 1 | CI6: =SUM(C6:CH6) -> 14 | CJ6: {=_xlfn.IFS(CI6=0,0,CI6>=1,CI6/CI25)} -> 0.15217391
A7: Caught on | CI7: =SUM(C7:CH7) -> 0 | CJ7: {=_xlfn.IFS(CI7=0,0,CI7>=1,CI7/CI25)} -> 0
A8: Fall on same level | AH8: 1 | BC8: 1 | BQ8: 1 | BX8: 1 | CI8: =SUM(C8:CH8) -> 4 | CJ8: {=_xlfn.IFS(CI8=0,0,CI8>=1,CI8/CI25)} -> 0.043478261
A9: Fall on Lower Level | U9: 1 | CI9: =SUM(C9:CH9) -> 1 | CJ9: {=_xlfn.IFS(CI9=0,0,CI9>=1,CI9/CI25)} -> 0.010869565
A10: Fall of material or structure | CI10: =SUM(C10:CH10) -> 0 | CJ10: {=_xlfn.IFS(CI10=0,0,CI10>=1,CI10/CI25)} -> 0
A11: Punctured | M11: 1 | AH11: 1 | AV11: 1 | CI11: =SUM(C11:CH11) -> 3 | CJ11: {=_xlfn.IFS(CI11=0,0,CI11>=1,CI11/CI25)} -> 0.032608696
A12: Over-exertion in lifting objects | CI12: =SUM(C12:CH12) -> 0 | CJ12: {=_xlfn.IFS(CI12=0,0,CI12>=1,CI12/CI25)} -> 0
A13: Over-exertion in pushing or pulling objects | CI13: =SUM(C13:CH13) -> 0 | CJ13: {=_xlfn.IFS(CI13=0,0,CI13>=1,CI13/CI25)} -> 0
A14: Over-exertion in handling or throwing objects | CI14: =SUM(C14:CH14) -> 0 | CJ14: {=_xlfn.IFS(CI14=0,0,CI14>=1,CI14/CI25)} -> 0
A15: Fire | BF15: 1 | CA15: 1 | CI15: =SUM(C15:CH15) -> 2 | CJ15: {=_xlfn.IFS(CI15=0,0,CI15>=1,CI15/CI25)} -> 0.02173913
A16: Eye contact with foreign object | CI16: =SUM(C16:CH16) -> 0 | CJ16: {=_xlfn.IFS(CI16=0,0,CI16>=1,CI16/CI25)} -> 0
A17: Contact with smoke | AA17: 1 | AO17: 1 | CI17: =SUM(C17:CH17) -> 2 | CJ17: {=_xlfn.IFS(CI17=0,0,CI17>=1,CI17/CI25)} -> 0.02173913
A18: Contact or exposure to extreme temperatures | CI18: =SUM(C18:CH18) -> 0 | CJ18: {=_xlfn.IFS(CI18=0,0,CI18>=1,CI18/CI25)} -> 0
A19: Exposure to radiation | CI19: =SUM(C19:CH19) -> 0 | CJ19: {=_xlfn.IFS(CI19=0,0,CI19>=1,CI19/CI25)} -> 0
A20: Contact with Object | BC20: 1 | CI20: =SUM(C20:CH20) -> 1 | CJ20: {=_xlfn.IFS(CI20=0,0,CI20>=1,CI20/CI25)} -> 0.010869565
A21: Contact with Electricity | AA21: 1 | CI21: =SUM(C21:CH21) -> 1 | CJ21: {=_xlfn.IFS(CI21=0,0,CI21>=1,CI21/CI25)} -> 0.010869565
A22: Contact with Chemical | AO22: 1 | CI22: =SUM(C22:CH22) -> 1 | CJ22: {=_xlfn.IFS(CI22=0,0,CI22>=1,CI22/CI25)} -> 0.010869565
A23: Occupational Illness/Pain | H23: 2 | O23: 1 | V23: 3 | AJ23: 2 | AX23: 2 | BE23: 2 | BL23: 1 | BS23: 1 | CI23: =SUM(C23:CH23) -> 14 | CJ23: {=_xlfn.IFS(CI23=0,0,CI23>=1,CI23/CI25)} -> 0.15217391
A24: Property Damage | I24: 2 | AK24: 2 | AR24: 2 | BK24: 1 | BT24: 1 | CI24: =SUM(C24:CH24) -> 8 | CJ24: {=_xlfn.IFS(CI24=0,0,CI24>=1,CI24/CI25)} -> 0.086956522
A25: TOTAL | C25: =SUM(C3:C24) -> 0 | D25: =SUM(D3:D24) -> 0 | E25: =SUM(E3:E24) -> 0 | F25: =SUM(F3:F24) -> 5 | G25: =SUM(G3:G24) -> 0 | H25: =SUM(H3:H24) -> 2 | I25: =SUM(I3:I24) -> 2 | J25: =SUM(J3:J24) -> 0 | ... CJ25: =SUM(CJ3:CJ24) -> 1
A27: Occupation/ Equipment | C27: January | J27: February | Q27: March | X27: April | AE27: May | AL27: June | AS27: July | AZ27: August | BG27: September | BN27: October | BU27: November | CB27: December | CI27: Total | CJ27: Total by Nature of Accident
C28: LTA-F | D28: LTA-NF | E28: NLTA | F28: FAC | G28: NM | H28: OI | I28: PD | J28: LTA-F | K28: LTA-NF | L28: NLTA | M28: FAC | N28: NM | O28: OI | P28: PD | Q28: LTA-F | R28: LTA-NF | S28: NLTA | T28: FAC | U28: NM | V28: OI | W28: PD | X28: LTA-F | Y28: LTA-NF | Z28: NLTA | AA28: FAC | AB28: NM | AC28: OI | AD28: PD | AE28: LTA-F | AF28: LTA-NF | AG28: NLTA | AH28: FAC | AI28: NM | AJ28: OI | AK28: PD | AL28: LTA-F | AM28: LTA-NF | AN28: NLTA | AO28: FAC | AP28: NM | AQ28: OI | AR28: PD | AS28: LTA-F | AT28: LTA-NF | AU28: NLTA | AV28: FAC | AW28: NM | AX28: OI | AY28: PD | AZ28: LTA-F | BA28: LTA-NF | BB28: NLTA | BC28: FAC | BD28: NM | BE28: OI | BF28: PD | BG28: LTA-F | BH28: LTA-NF | BI28: NLTA | BJ28: FAC | BK28: NM | BL28: OI | BM28: PD | BN28: LTA-F | BO28: LTA-NF | BP28: NLTA | BQ28: FAC | BR28: NM | BS28: OI | BT28: PD | BU28: LTA-F | BV28: LTA-NF | BW28: NLTA | BX28: FAC | BY28: NM | BZ28: OI | CA28: PD | CB28: LTA-F | CC28: LTA-NF | CD28: NLTA | CE28: FAC | CF28: NM | CG28: OI | CH28: PD
A29: Assistant Miner
A30: Lead Miner
A31: LHD/ LPT Optr
A32: Locomotive Optr./ Helper
A33: Shiftboss
A34: Driller/ Drill Helper
A35: Loco. Optr./ Helper
A36: Track Man
A37: Maintenance Man (GMS)
A38: UG Warehouse Man (IMD)
A39: Maintenance Man (MME)
A40: Mine Patrol
... A49: Main Entry Door of Housing
...

Sheet SCAT Reference
B1: System Cause Analysis Technique (SCAT)
A3: # | B3: Types of Contact | C3: I/D Causes | E3: # | F3: Immediate / Direct Causes | G3: B/U Causes | I3: # | J3: - | K3: Basic / Underlying Causes | L3: -2 | M3: CAN | O3: # | P3: - | Q3: Control Action Needs | R3: Program Activity | S3: Program Standards are Established | T3: Full Compliance to Standards Achieved
A4: 1 | B4: Struck Against (Running or Bumping Into) | C4: 1,2,4,5,12,14-19,26 | F4: Substandard Acts | K4: Personal Factors | R4: Accomplishment Levels
A5: 2 | B5: Struck By (Hit by Moving Object) | C5: 1,2,4-6,9,10,12-16,20,26 | E5: 1 | F5: Operating Equipment without Authority | G5: 2,4,5,7,8,12,13,15 | I5: 1 | J5: Inadequate Physical / Physiological Capabality | M5: 6,9,12,15,18
A6: 3 | B6: Fall From Elevation to Lower Level | C6: 1,3,5-7,11-17,22 | E6: 2 | F6: Failure to Warn | G6: 1-9,12,13,15 | J6: 1.1 | K6: Inappropriate height, weight, size, strength, reach, etc. | O6: 1 | P6: Leadership and Administration
A7: 4 | B7: Fall on Same Level (Slip & Fall, Trip Over) | C7: 4,9,13-16,19,22,26 | E7: 3 | F7: Failure to Secure | G7: 2-9,12,13,15 | J7: 1.2 | K7: Restricted range of body movement | P7: 1.2 | Q7: Loss Control Coordinator
A8: 5 | B8: Caught On (Snegged / Hung) | C8: 5,6,11,13,14-16,18 | E8: 4 | F8: Operating at Improper Speed | G8: 2-9,11-13,15 | J8: 1.3 | K8: Limited ability to sustain body positions | P8: 1.3 | Q8: Senior and Middle Management Participation
A9: 6 | B9: Caught Between or Under (Crushed or Amputated) | C9: 5,6,11-16,18 | E9: 5 | F9: Making Safety Devices Inoperative | G9: 2-9,12,13,15 | J9: 1.4 | K9: Substance sensitivities / allergies | P9: 1.4 | Q9: Establish Loss Control Performance Strandards
A10: 7 | B10: Contact With (Electricity, Heat, Cold, Radiation, Caustics, Toxics, Biological, Noise) | C10: 1,2,5,6,9,11-16,22,28 | E10: 6 | F10: Using Defective Equipment | G10: 2-15 | J10: 1.5 | K10: Sensitivities to sensory extremes (temperature, sound, etc.) | P10: 1.5 | Q10: Participation in Special Loss Control Activities
A11: 8 | B11: Overstress (Overexertion, Overload, Overexposure, Ergonomic) | C11: 5-7,11-18,20,21,23-25, 27,28 | E11: 7 | F11: Failing to Use PPE Properly | G11: 2-5,7,8,10,12,13,15 | J11: 1.6 | K11: Vision deficiency | P11: 1.6 | Q11: Agenda Item in Management Meetings
E12: 8 | F12: Improper Loading | G12: 1-9,11-13,15 | J12: 1.7 | K12: Hearing deficiency | P12: 1.7 | Q12: Loss Control Reference Manual
E13: 9 | F13: Improper Placement | G13: 1-9,12,13,15 | J13: 1.8 | K13: Other sensory deficiency (touch, taste, smell, balance) | P13: 1.8 | Q13: Internal Audits Conducted
E14: 10 | F14: Improper Lifting | G14: 1-9,12,13,15 | J14: 1.9 | K14: Respiratory Incapability | P14: 1.9 | Q14: Individual Responsibility for Loss Control Assigned
E15: 11 | F15: Improper Position for Task | G15: 1-9,12,13,15 | J15: 1.10 | K15: Other permanent physical capabilities | P15: 1.10 | Q15: Annual Loss Control Objectives Established
E16: 12 | F16: Servicing Equipment in Operation | G16: 2-9,12,13,15 | J16: 1.11 | K16: Temporary disabilities | P16: 1.11 | Q16: Joint Safety and Health Committees and / or Safety and Health Representatives
E17: 13 | F17: Horseplay | G17: 2-5,7,8,13,15 | I17: 2 | J17: Inadequate Mental / Psychological Capability | M17: 6,9,10,15,18 | P17: 1.12 | Q17: Policy on Refusal to work due to hazards
E18: 14 | F18: Under Influence of Alcohol and / or Other Drugs | G18: 2-5,7,8,13,15 | J18: 2.1 | K18: Fear and phobias | P18: 1.13 | Q18: Reference Library
E19: 15 | F19: Using Equipment Improperly | G19: 1-10,12,13,15 | J19: 2.2 | K19: Emotional disturbance | P19: 1.14 | Q19: Document Control System
F20: Substandard Conditions | J20: 2.3 | K20: Mental Illness | P20: 1.15 | Q20: Applicable regulations, Codes and Standards Identified
E21: 16 | F21: Inadequate Guards / Barriers | G21: 5,7-13,15 | J21: 2.4 | K21: Intelligence level | P21: 1.16 | Q21: Communicating with External parties
E22: 17 | F22: Inadequate / Improper Protective Equipment | G22: 5,7-10,12,13 | J22: 2.5 | K22: Inability to comprehend | O22: 2 | P22: Leadership Training
E23: 18 | F23: Defective Tools, Equipment or Materials | G23: 8-13 | J23: 2.6 | K23: Poor judgement | P23: 2.1 | Q23: Training Needs Analysis
E24: 19 | F24: Congestion or Restricted Action | G24: 8,9,13 | J24: 2.7 | K24: Poor coordination | P24: 2.2 | Q24: Loss Control Orientation / Induction for New Leaders / Managers
E25: 20 | F25: Inadequate Warning System | G25: 8-15 | J25: 2.8 | K25: Slow reaction time | P25: 2.3 | Q25: Initial Training of Senior Management
E26: 21 | F26: Fire and Explosion Hazards | G26: 5-13, 15 | J26: 2.9 | K26: Low mechanical aptitude | P26: 2.4 | Q26: Update Training of Senior Management
E27: 22 | F27: Poor Housekeeping / Disporder | G27: 5-13, 15 | J27: 2.10 | K27: Low learning aptitude | P27: 2.5 | Q27: Initial Loss Control Training for Leaders / Managers
E28: 23 | F28: Noise Exposure | G28: 5-14 | J28: 2.11 | K28: Memory failure | P28: 2.6 | Q28: Update Loss Control Training for Leaders / Managers
E29: 24 | F29: Radiation Exposure | G29: 5-14 | I29: 3 | J29: Physical / Physiological Stress | M29: 4,6,9,11-13,15,18,20 | P29: 2.7 | Q29: Formal Training of Loss Control Coordinator
E30: 25 | F30: Temperature Extremes | G30: 1-3,8,9,11,12 | J30: 3.1 | K30: Injury / Illness | P30: 2.8 | Q30: Records of Leadership Training
E31: 26 | F31: Inadequate / Excess Illumination | G31: 8-12 | J31: 3.2 | K31: Fatigue due to task load / duration | O31: 3 | P31: Planned Inspection and Maintenance
E32: 27 | F32: Inadequate Ventilation | G32: 8-13 | J32: 3.3 | K32: Fatigue dur to lack of rest | P32: 3.1 | Q32: Planned General Inspections
E33: 28 | F33: Hazardous Environment Conditions | G33: 8-11 | J33: 3.4 | K33: Fatigue due to sensory overload | P33: 3.2 | Q33: Forllow-up System
J34: 3.5 | K34: Exposure to health hazards | P34: 3.3 | Q34: Inspection Report Analysis
J35: 3.6 | K35: Exposure to temperature extremes | P35: 3.4 | Q35: Critical Parts / Items Inpections
J36: 3.7 | K36: Oxygen deficiency | P36: 3.5 | Q36: Preventive Maintenance System
J37: 3.8 | K37: Atmospheric pressure constrained movement | P37: 3.6 | Q37: Special Systemas Inspections
J38: 3.9 | K38: Constrained movement | P38: 3.7 | Q38: Pre-use Equioment Inspections
J39: 3.10 | K39: Blood sugar insufficiency | P39: 3.8 | Q39: System for Employees to report Substandard Conditions in Writing
J40: 3.11 | K40: Drugs | P40: 3.9 | Q40: Compliance with Regulatory Requirements for Inspections
I41: 4 | J41: Mental / Psychological Stress | M41: 1,4,-6,9-12,15,16,18,20 | O41: 4 | P41: Critical Task Analysis Procedure
...

Sheet DataReferences
A1: MMMM-YYYY | B1: Section | C1: Occupation / Designation / Property | D1: Workplace / Area | E1: Level | F1: Shift | G1: Department Heads | H1: Section Heads | I1: Immediate Supervisor | J1: Nature of Injury | K1: Type of Incident | L1: Group | M1: Department | N1: Section | O1: Group / Dept. / Sect. | P1: Recorder | Q1: GENERAL MANAGEMENT: | R1: ADMINISTRATIVE SVCS. GROUP: | S1: FINANCE SERVICES GROUP: | T1: TECHNICAL SERVICES GROUP: | U1: MINE GROUP: | V1: MINE ENG'G,GEOLOGY AND VENT: | W1: EXPLORATION GROUP: | X1: MILL GROUP:
A2: JANUARY, 2026 | B2: Surface | C2: N/A | D2: Aerodome Area | E2: S (N/A) | F2: First | G2: N/A | H2: N/A | I2: N/A | J2: LTA-F | K2: Struck by Falling Rock | L2: N/A - Community | M2: N/A - Community | N2: N/A - Community | O2: N/A - Emergency Incident | P2: MAAT | Q2: General Management Office | R2: Legal Services | S2: Accounting | T2: Technical Management Office | U2: Mining | V2: Engineering | W2: Exploration | X2: Mill Management
A3: FEBRUARY, 2026 | B3: Underground | C3: Assistant Miner | D3: Assay Laboratory | E3: 670L | F3: Second | G3: Abraham L. Davis | H3: Alfon B. Yodong | I3: Allan F. Takayeng | J3: LTA-NF | K3: Struck by Flying Object | L3: Contracts | M3: Dept. 1 | N3: Contracts | O3: MOG - 1: Section 1 | P3: KTAA | Q3: Safety Department | R3: Administrative Management | S3: Purchasing | T3: Enercon | U3: Mine Management | V3: Geology | X3: Mill Operations
A4: MARCH, 2026 | C4: Cadet Mechanical Engineer | D4: Breast Hole | E4: 800L | F4: Third | G4: DDCP - Allan R. Domalsin | H4: Allab B. Lal-wet | I4: Andy M. Delumen | J4: NLTA | K4: Struck by Object | L4: ASG | M4: Dept. 2 | N4: Section 1 | O4: MOG - 1: Section 2 | P4: MBM | Q4: MEPEO | R4: IOSD-Communication & AS | S4: Inventory Management Dept. | T4: Project Engineering, Surf. Survey & SWM | U4: General Mine Services( A&W,TSO,NSO, UG Sandfilling, UG Crushing, Haulage,UG Cons. & Special Projects) | V4: Mine Ventilation | X4: Metallurgical Laboratory
A5: APRIL, 2026 | C5: Carpenter | D5: Boiler Room Extension | E5: 830L | G5: Dexter B. Arevalo | H5: Art Benzene E. Lanip | I5: Angelito A. Delim | J5: NM | K5: Struck Against | L5: Exploration | M5: MMME | N5: Section 2 | O5: MOG - 1: Section 3 | P5: AOV | Q5: SDD | R5: Medical Dept. | T5: Mechanical Workshops (Machine,Fabrication, Overhauling & TSG-Mine Shops) | U5: Mine Mechanical & Electrical | X5: Tamangan Lime Plant
A6: MAY, 2026 | C6: CIP Operator | D6: Bonanza Quarry, TSF | E6: 840L | G6: Fabrian Roderick S. Likigan | H6: Baker S. Calbid | I6: Antonio D. Siyao | J6: FAC | K6: Caught on | L6: FSG | M6: GMS | N6: Section 3 | O6: MOG - 2: Section 4 | P6: HMBR | Q6: Communication Dept. | R6: HR | T6: Surface Mechanical & Electrical (Trans.Svcs., Power Plant, Surface Elect'l.Svcs., Instrument Calib.) | U6: ADIT Rehab | X6: Upper and Lower Tram Operations
A7: JUNE, 2026 | C7: Crusher Operator | D7: Buaki, Sapid | E7: 850L | G7: Fe Marie W. Mates | H7: Benito A. Islao Jr. | I7: Ambros C. Gabriel | J7: OI | K7: Caught in Between | L7: GMG | M7: Safety | N7: Section 4 | O7: MOG - 2: Section 5 | Q7: MISD | X7: Mill Mechanical & Electrical
A8: JULY, 2026 | C8: DeviGyro HQ Mid Centralizer | D8: Bulalacao, Mankayan, Benguet | E8: 860L | G8: Fernando A. Bustillo Jr. | H8: Bullet P. Tangcalagan | I8: Art Benzene E. Lanip | J8: PD | K8: Fall on Same Level | L8: MEGG | M8: Mine Management | N8: Section 5 | O8: MOG - 2: Section 6 | Q8: Tailings Storage Facility | X8: Mill Eng'g.-PCEA's
A9: AUGUST, 2026 | C9: Drill Helper / Drilling Aide | D9: Carpentry Shop | E9: 870L | G9: Hilbert G. Andong | H9: Christopher T. Baniaga | I9: Arthur M. Padica | J9: EI | K9: Fall on Lower level | L9: MOG | M9: Mine Engineering | N9: Section 6 | O9: MOG - MMME - Mobile | Q9: Waste Water Management
A10: SEPTEMBER, 2026 | C10: Electrician | D10: Casubigan / Marivic Area | E10: 880L | G10: Jayson T. Capia-ao | H10: Darwin S. Coloma | I10: Aquino P. Lawana Jr. | K10: Punctured | L10: MPG | M10: Mine Study | N10: Mine Technical Services | O10: MOG - MMME - Non-Mobile | Q10: Assay
A11: OCTOBER, 2026 | C11: Forest Fire | D11: Casubigan, Sapid | E11: 900L | G11: John Paul C. Licot | H11: DDCP - Allan Raymund Domalsin | I11: Bernard M. Itliong | K11: Over-Exertion in Lifting Objects | L11: TSG | M11: Mine Geology | N11: Mobile | O11: MOG - MMME - Electrical
A12: NOVEMBER, 2026 | C12: Fuse Cut-Off Switch | D12: Chute | E12: 970L | G12: Kay B. Lacambra | H12: Dember F. Dictaan Jr. | I12: Clinton O. Lingyasan | K12: Over-Exertion in Pushing / Pulling Objects | M12: Mine Ventilation | N12: Non-Mobile | O12: MOG - GMS - Nayak Shaft / UG Construction
A13: DECEMBER, 2026 | C13: Garbage Fire | D13: CIP - Barren Pump Area | E13: 980L | G13: Kurt Linis Ljomir Ursua | H13: Dimas S. Gao-ay | I13: Danilo M. Galande | K13: Over-Exertion in Handling or Throwing Objects | M13: TSF 5A | N13: Electrical | O13: MOG - GMS - Tubo Shaft
C14: Geologic Sampler | D14: CIP - ILR | E14: 1000L | G14: Larry E. Arigue | H14: Edie S. Pacsay | I14: DDCP - Allan Kitma | K14: Fire | M14: Mill Operations | N14: Stope Services Crew | O14: MOG - GMS - Drift and Track Maintenance
C15: Geotech Aide | D15: CIP - Refinery | E15: 1040L | G15: Lourdes F. Inao | H15: Ernesto L. Locaben Jr. | I15: DDCP - Clarence Avila | K15: Contact with Object | M15: Mill Mechanical | N15: Nayak Shaft Operation / UG Construction | O15: MOG - GMS - Underground Crusher
C16: Grade Application Analyst | D16: Cone Crusher Conveyor Feed | E16: 1100L | G16: Mary Grace C. Torres | H16: Florence S. Sayson | I16: Dominador B. Dampilag | K16: Contact with Smoke | M16: Mill Electrical | N16: Tubo Shaft Operation / 670L Pumping | O16: MOG - GMS - Adit 1&2
C17: Grinding Operator | D17: Crushing Area | E17: 1150L | G17: Michael P. Lamagan - OIC | H17: Francis E. Mabunga | I17: Dummory Joseff Febrei O. Estepa | K17: Contact / Exposure to Extreme Temperatures | M17: Mill Engineering | N17: Underground Crusher | O17: MOG - GMS - Air and Water
C18: Head Nurse | D18: Cuddy | E18: 1250L | G18: Nelson L. Baguya II | H18: James I. Consolacion | I18: Efren L. Mangamti | K18: Exposure to Extreme Temperatures | M18: Metallurgy | N18: Main Haulage / Drift & Track Maintenance | O18: MOG - Safety - Surface Safety
C19: Heavy Equipment Operator | D19: Development | G19: Richard C. Ducusin | H19: Jeah B. Taguran | I19: Ernie S. Ringor | K19: Exposure to Radiation | M19: Assay | N19: Surface Safety | O19: MOG - Safety - Nayak/UG Safety
C20: Jr. Machinist | D20: Fuel Storage Area | G20: Rolando E. Ventura | H20: Jenipher B. Rosito | I20: Ephraim K. Pitok | K20: Foreign Object in the Eye/s | M20: Mill Management | N20: Nayak/UG Safety | O20: MOG - Mine Management
C21: Jr. Maintenance Man | D21: IMD Substation | G21: SNSAI - Mary Joyce Adaclog - OIC | H21: Jeric T. Dulawan | I21: Eufrosino A. De Leon Jr. | K21: Eye Contact with Foreign Object | M21: Exploration | N21: Control | O21: EXPLO - Exploration
C22: Jr. Mechanic | D22: Gate 1, Panad | G22: Venancio A. Bad-ay | H22: Jerry G. Gatinao Jr. | I22: Frank C. Samdao Jr. | K22: Occupational Illness / Pain | M22: MEPEO | N22: Refinery | O22: MEGG - Mine Engineering
C23: Jr. Mechanic / Driver | D23: Golf Course, Sapid | G23: Zerubabel D. Pateña | H23: Jet Lee V. Chinanglas | I23: Higenio Ginpac - Consultant | K23: Property Damage | M23: ComRel | N23: CIP | O23: MEGG - Mine Study
C24: Jr. Mechanical Engineer | D24: Gravel Pit, Sapid | H24: Jordan P. Masidong | I24: Jefferson V. Ramos | K24: Near Miss | M24: MWSO | N24: Services | O24: MEGG - Mine Geology
C25: Kalalaw Truck | D25: Hoist Room | H25: Julian Manuel S. Casuga | I25: Jerry I. Garwageo | K25: Earthquake | M25: SMED | N25: Crushing & Grinding | O25: MEGG - Mine Ventilation
C26: Laboratory Technician | D26: Hospital | H26: Julius B. Liban | I26: Joel M. Lopez | K26: Environmental Incident - Chemical Spill | M26: PCES | N26: Sand Production | O26: MEGG - Rock Mechanics
C27: Lead Miner | D27: La Guerta Area | H27: Julius K. Finatec | I27: John I. Naweywey | K27: Explosion | M27: IOSD | N27: Water Recovery | O27: MPG - Mill Operations - Refinery
C28: LHD Optr | D28: Lime Plant | H28: June O. Golocan | I28: John Pauline M. Refugia | M28: Legal Office | N28: Fabrication Shop | O28: MPG - Mill Operations - CIP
C29: Leach Tank | D29: LMD Hospital | H29: Keziah C. Chamollog | I29: John Ray T. Salguit | M29: Human Resources | N29: Overhauling Shop | O29: MPG - Mill Operations - Services
C30: Lifting Equipment | D30: LMD Morgue Area | H30: Mariel T. Ayong | I30: Karl Lloyd S. Valentin | M30: Medical Services | N30: 900L Mine Shop | O30: MPG - Mill Operations - Sand Production
C31: Lime Surge Tank | D31: LMD Roadway | H31: Melno S. Palayen | I31: Kathy M. Domogo | M31: DDCP | N31: Machine Shop | O31: MPG - Mill Operations - Water Recovery
C32: Locomotive Optr. / Helper | D32: Loading Bay | H32: Nathaneal D. Jugal | I32: Kristian Lloyd D. Bulay | M32: MD&C Construction | N32: Surface Electrical | O32: MPG - Mill Operations - Crushing & Grinding
C33: LPT Optr | D33: Lower Tram | H33: Neil Marcel F. Paquito | I33: Larry S. Andomang | M33: VSAI | N33: Powerplant, Nayak & Tubo Compressor | O33: MPG - Mill Mechanical
C34: Maintenance Man (GMS) | D34: Machine Shop | H34: Reynaldo G. Cawi | I34: Lambert I. Domogen Jr. | M34: SNSAI | N34: Energy Conservation | O34: MPG - Mill Engineering
C35: Maintenance Man (MMME) | D35: Mainline / Access | H35: Reynaldo P. Kiking | I35: Leo D. Bulawit | M35: RBDanao | N35: Instrument Calibration | O35: MPG - Metallurgy - Laboratory
C36: Maintenance Man (PCES) | D36: Marivic Rd., Sapid | H36: Ruben T. Saliwey | I36: Leonard K. Fawayan | M36: Accounting | N36: Motorpool / Transport | O36: TSG - MWSO - Fabrication Shop
C37: Maintenance Man (TSF) | D37: Mill Office | H37: Samson A. Fotyong | I37: Mark D. Banasan | M37: IMD | N37: Project Engineering | O37: TSG - MWSO - Overhauling Shop
C38: Mill Engineering Service Vehicle | D38: Nayak Mine Office Compound | H38: Randolf O. Anongos | I38: Marry Joy S. Ronulo | N38: Surface Survey | O38: TSG - MWSO - 900L Mine Shop
C39: Mill Mechanical ADH | D39: Old Gate 3 | H39: Wendel D. Balag-ey | I39: Marvin B. Caligner | N39: Solid Waste & Tamangan ESL Management | O39: TSG - MWSO - Machine Shop
C40: Mill Mechanical Fitter | D40: Old Traffic Area / Junction | I40: Mauricio D. Bangngayon | N40: Carpentry Shop | O40: TSG - MWSO - Motorpool
...

Sheet input
A1: MONTH - YEAR | B1: SECTION (SURFACE / UNDERGROUND) | C1: VICTIM / DAMAGED PROPERTY | D1: CN / Unit # | E1: OCCUPATION / DESIGNATION | F1: TYPE OF INCIDENT | G1: WORKPLACE / AREA | H1: LEVEL | I1: DATE | J1: TIME | K1: SHIFT | L1: DEPARTMENT HEAD | M1: SECTION HEAD | N1: IMMEDIATE SUPERVISOR | O1: NATURE OF INJURY | P1: ON-GOING ACTIVITY | Q1: SAFETY INSPECTOR ON DUTY | R1: GROUP | S1: DEPARTMENT | T1: SECTION | U1: RECORDED BY | V1: OTHER INFO.: LOCATION | W1: HEADS | X1: GRP/DEPT/SECT | Y1: MEDICAL FINDINGS | Z1: DETAILS OF TREATMENT PROVIDED | AA1: REHABILITATION PLAN | AB1: Unsafe Acts | AC1: Personal Factors | AD1: Unsafe Conditions | AE1: Job Factors
A2: JANUARY, 2026 | B2: Underground | C2: RYAN DAVE MAWI-IT | D2: 8471 | E2: Assistant Miner | F2: Occupational Illness / Pain | G2: Shaft Station / Resting Area | H2: 900L | I2: 46032 | J2: 0.97916667 | K2: Second | L2: Hilbert G. Andong | M2: Reynaldo P. Kiking | N2: Stephen Adams D. Mamanteo | O2: OI | P2: Cleaning of canal. | Q2: WDL / MAT | R2: MOG | S2: Dept. 2 | T2: Section 6 | U2: MAT | V2: RP No. 22 | W2: HGA / RPK / SADM | X2: MOG - 2: Section 6
A3: JANUARY, 2026 | B3: Underground | C3: JOEY A. LASSIN | D3: 9728 | E3: Assistant Miner | F3: Struck by Falling Rock | G3: Stope | H3: 970L | I3: 46038 | J3: 0.97916667 | K3: Second | L3: Venancio A. Bad-ay | M3: Mariel T. Ayong | N3: Leonard K. Fawayan | O3: FAC | P3: Rock Bolting | Q3: JAW / EAR / MAT / AOV | R3: MOG | S3: Dept. 1 | T3: Section 2 | U3: MAT | V3: 21516 4M4 | W3: VAB / MTA / LKF | X3: MOG - 1: Section 2 | Y3: MULTIPLE PHYSICAL INJURY | Z3: WOUND CARE. XRAY OF LEFT KNEE,LSV,TCAGE, ANTIBIOTIC, ANALGESIC, TETANUS TOXOID. | AA3: ADMITTED AT THE HOSPITAL FOR HEALING
A4: JANUARY, 2026 | B4: Underground | C4: MANUEL D. BALAIS | D4: 1209 | E4: Shiftboss | F4: Foreign Object in the Eye/s | G4: Ramp | H4: 1100L | I4: 46046 | J4: 0.125 | K4: First | L4: Hilbert G. Andong | M4: Allab B. Lal-wet | N4: Dummory Joseff Febrei O. Estepa | O4: FAC | P4: Operating the breaker | Q4: WLT / SUU / FPP | R4: MOG | S4: Dept. 2 | T4: Section 4 | U4: MAT | V4: 305 RAMP | W4: HGA / ABL / DJFOE | X4: MOG - 2: Section 4
A5: JANUARY, 2026 | B5: Underground | C5: WILBUR D. AWIS | D5: 9940 | E5: Maintenance Man (MMME) | F5: Occupational Illness / Pain | G5: Shaft Station / Resting Area | H5: 900L | I5: 46047 | J5: 0.29166667 | K5: Second | L5: Fernando A. Bustillo Jr. | M5: Alfon B. Yodong | N5: John Pauline M. Refugia | O5: OI | P5: Preparing for task | Q5: SUU | R5: MOG | S5: MMME | T5: Mobile | U5: MAT | V5: RP No. 22 | W5: FABJr. / ABY / JPMR | X5: MOG - MMME - Mobile
A6: JANUARY, 2026 | B6: Underground | C6: DUMAGUING M. LIBAN | D6: 1336 | E6: LHD Optr | F6: Caught in Between | G6: Ramp | H6: 1000L | I6: 46048 | J6: 0.8125 | K6: Third | L6: Venancio A. Bad-ay | M6: June O. Golocan | N6: Danilo M. Galande | O6: LTA-F | P6: Descending towards 900L | Q6: WLT / EAR | R6: MOG | S6: Dept. 1 | T6: Section 3 | U6: MAT | V6: 207 K Ramp, 1012 Elevation | W6: VAB / JOG / DMG | X6: MOG - 1: Section 3 | Y6: IMMEDIATE CAUSE: MECHANICAL ASPHYXIA ANTECEDENT CAUSE: CRUSHING INJURY TO THE TORSO UNDERLYING CAUSE: CAUGHT BETWEEN THE HEAVY EQUIPMENT AND A MUCK PILE | Z6: N/A | AA6: N/A
A7: JANUARY, 2026 | B7: Underground | C7: GLENN MARK B. LABOTAN | D7: 9346 | E7: UG Senior Warehouseman | F7: Caught in Between | G7: Fuel Storage Area | H7: 900L | I7: 46052 | J7: 0.40625 | K7: Second | L7: Fe Marie W. Mates | M7: Samson A. Fotyong | N7: Marvin B. Caligner | O7: LTA-NF | P7: Unloading fuel oil drum | Q7: MAT / AOV | R7: FSG | S7: IMD | T7: Underground Warehouse | U7: KTA | V7: C30 Fuel Storage | W7: FMWM / SAF / MBC | X7: FSG - IMD - Underground Warehouse | Y7: AVULSED WOUND, OPEN FRACTURE 2ND/3RD DISTAL PHALANX LEFT HAND | Z7: WOUND SUTURING WITH AMPUTATION OF DISTAL PHALANX 2ND DIGIT LEFT HAND | AA7: FOR RUTHER MEDICAL EVALUATION
A8: JANUARY, 2026 | B8: Surface | C8: BINSON I. ZAPARITA | D8: 9901 | E8: Jr. Machinist | F8: Caught in Between | G8: Machine Shop | H8: S (N/A) | I8: 46039 | J8: 0.46527778 | K8: Second | L8: Larry A. Arigue | M8: James I. Consolacion | N8: N/A | O8: FAC | P8: Unloading via crane operation | Q8: MBK / RML | R8: TSG | S8: MWSO | T8: Machine Shop | U8: RML | V8: N/A | W8: LAA / JIC / - | X8: TSG - MWSO - Machine Shop | Y8: AVULSED WOUND, 4TH DIGIT, RIGHT HAND | Z8: WOUND IRRIGATION AND PACKING, ATS, TT VACCINE, ANALGESIC, XRAY. | AA8: TRANSFERRED TO LUIS HORA FOR FURTHER MANAGEMENT
A9: JANUARY, 2026 | B9: Surface | C9: ROWELL C. DELA CRUZ | D9: 9386 | E9: Surface Warehouseman | F9: Contact with Object | G9: Steel Yard | H9: S (N/A) | I9: 46034 | J9: 0.32291667 | K9: Second | L9: Fe Marie W. Mates | M9: Julian Manuel S. Casuga | N9: Karl Lloyd S. Valentin | O9: FAC | P9: Loading of Causic Soda | Q9: ENC / RML | R9: FSG | S9: IMD | T9: Surface Warehouse | U9: RML | V9: N/A | W9: FMWM / JMSC / KLSV | X9: FSG - IMD - Surface Warehouse | Y9: CHEMICAL BURN LEFT FOOT SECONDARY TO METABISULFITE | Z9: WOUND DEBRIDEMENT/DRESSING
A10: JANUARY, 2026 | B10: Surface | C10: JOHN REY BAGUIYAC | D10: N/A - Contracts | E10: Carpenter | F10: Caught in Between | G10: Hospital | H10: S (N/A) | I10: 46045 | J10: 0.33333333 | K10: Second | L10: Abraham L. Davis | M10: Nathaneal D. Jugal | N10: Kathy M. Domogo | O10: FAC | P10: Hauling of H-beams | Q10: ENC / RML | R10: Contracts | S10: MD&C Construction | T10: Building Maintenance | U10: RML | V10: Proposed Hemodialysis Station | W10: Contracts - MD&C Construction | X10: Contracts - MD&C Construction
A11: JANUARY, 2026 | B11: Surface | C11: FUSE CUT-OFF SWITCH | D11: N/A - PD | E11: Fuse Cut-Off Switch | F11: Property Damage | G11: UG Crusher | H11: S (N/A) | I11: 46039 | J11: 0.77083333 | K11: Third | L11: Fernando A. Bustillo Jr. | M11: Neil Marcel F. Paquito | N11: Pedro B. Lambino | O11: PD | P11: Sudden Power Loss | Q11: MBK | R11: MOG | S11: MMME | T11: Electrical | U11: KTA | V11: 300 KVA Substation | W11: FABJr. / NMFP / PBL | X11: MOG - MMME - Electrical
A12: JANUARY, 2026 | B12: Surface | C12: PINE TREES | D12: N/A - EI | E12: Forest Fire | F12: Fire | G12: Buaki, Sapid | H12: S (N/A) | I12: 46043 | J12: 0.66666667 | K12: Second | L12: N/A | M12: N/A | N12: N/A | O12: EI | Q12: MBK | R12: ASG | S12: IOSD | T12: N/A - Community | U12: KTA | W12: N/A | X12: N/A - Emergency Incident
A13: JANUARY, 2026 | B13: Surface | C13: BURNT GARBAGE | D13: N/A - EI | E13: Forest Fire | F13: Fire | G13: Golf Course, Sapid | H13: S (N/A) | I13: 46046 | J13: 0.82361111 | K13: Third | L13: N/A | M13: N/A | N13: N/A | O13: EI | Q13: ENC | R13: ASG | S13: IOSD | T13: N/A - Community | U13: KTA | W13: N/A | X13: N/A - Emergency Incident | Y13: N/A
A14: JANUARY, 2026 | B14: Surface | C14: VOLVO TRUCK | D14: TDQ 954 | E14: Shipside - Volvo Truck | F14: Fall on Lower level | G14: Tubo, Sapid | H14: S (N/A) | I14: 46052 | J14: 0.29027778 | K14: Second | L14: N/A | M14: N/A | N14: N/A | O14: EI | P14: Delivery of goods | Q14: MBK | R14: FSG | S14: IMD | T14: Surface Warehouse | U14: KTA | W14: N/A | X14: N/A - Emergency Incident
A15: FEBRUARY, 2026 | B15: Underground | C15: NOREL ALAGON | D15: N/A - Contracts | E15: Drill Helper / Drilling Aide | F15: Struck by Object | G15: Cuddy | H15: 1000L | I15: 46062 | J15: 0.625 | K15: Second | L15: Venancio A. Bad-ay | M15: DDCP - Allan Raymund Domalsin | N15: DDCP - Clarence Avila | O15: FAC | P15: Retreiving inner drill tube | Q15: WDL / RWV | R15: Contracts | S15: DDCP | T15: Section 3 | U15: MAT | V15: LM90 Cuddy | W15: VAB / ARD / CTA | X15: Contracts - DDCP
A16: FEBRUARY, 2026 | B16: Underground | C16: JULUIS M. FANGGOT | D16: 9027 | E16: Assistant Miner | F16: Caught in Between | G16: Raise | H16: 1000L | I16: February 11, 2026 | J16: 0.72569444 | K16: Third | L16: Venancio A. Bad-ay | M16: June O. Golocan | N16: Jerry I. Garwageo | O16: LTA-NF | P16: Hand Mucking | Q16: RWV / FPP | R16: MOG | S16: Dept. 1 | T16: Section 3 | U16: MAT | V16: 21516 Raise Access | W16: VAB / JOG / JIG | X16: MOG - 1: Section 3 | Y16: Fracture Closed Non-Displaces Medial Malleolus Left Tibia | Z16: Short Posterior Mold L Foot | AA16: Week 0-2: Immobilization. Maintain cast, non-weight bearing, with crutches; Week 2-6: Continue Immobilization. Partial Weight bearing; Week 6-8: Full weight bearing as tolerated. Light work and activity Week 8-12: Return to full activity
A17: FEBRUARY, 2026 | B17: Underground | C17: ALJON J. VALDEZ | D17: 1 | E17: Lead Miner | F17: Occupational Illness / Pain | G17: Shaft Station / Resting Area | H17: 900L | I17: February 15, 2026 | J17: 0.90277778 | K17: Third | L17: Venancio A. Bad-ay | M17: Dimas S. Gao-ay | N17: Regie D. Espinosa | O17: OI | P17: Resting | Q17: ACBJr. | R17: MOG | S17: Dept. 1 | T17: Section 1 | U17: MAT | V17: 249 Station 900L | W17: VAB / DSG / RDE | X17: MOG - 1: Section 1
A18: FEBRUARY, 2026 | B18: Underground | C18: RAMIL A BAYYOC | D18: 7844 | E18: Maintenance Man (GMS) | F18: Occupational Illness / Pain | G18: Shaft Station / Resting Area | H18: 900L | I18: February 16, 2027 | J18: 0.35416667 | K18: Second | L18: Jayson T. Capia-ao | M18: Julius B. Liban | N18: Ephraim K. Pitok | O18: OI | P18: Waiting for the locomotive to charge | Q18: WDL/MAT/ AOV | R18: MOG | S18: GMS | T18: Nayak Shaft Operation / UG Construction | U18: MAT | V18: 249 Station 900L | W18: JTC / JBL / EKP | X18: MOG - GMS - Nayak Shaft / UG Construction
A19: FEBRUARY, 2026 | B19: Underground | C19: WILLARD S. BAGYON | D19: 621 | E19: Assistant Miner | F19: Occupational Illness / Pain | G19: Mainline / Access | H19: 980L | I19: February 19, 2028 | J19: 0.14583333 | K19: First | L19: Venancio A. Bad-ay | M19: Mariel T. Ayong | N19: Frank C. Samdao Jr. | O19: OI | P19: Jack up Activity | Q19: JAW | R19: MOG | S19: Dept. 1 | T19: Section 2 | U19: MAT | V19: 2091 Access 980L | W19: VAB / MTA / FCSJr | X19: MOG - 1: Section 2
A20: FEBRUARY, 2026 | B20: Underground | C20: JHON JHON B. ANGDASON | D20: 30 | E20: Assistant Miner | F20: Caught in Between | G20: Stope | H20: 870L | I20: February 20, 2029 | J20: 0.10416667 | K20: First | L20: Hilbert G. Andong | M20: Reynaldo P. Kiking | N20: Allan F. Takayeng | O20: FAC | P20: Hand Mucking | Q20: JAW | R20: MOG | S20: Dept. 2 | T20: Section 6 | U20: MAT | V20: 12541 G31S | W20: HGA / RPK / AFT | X20: MOG - 2: Section 6
A21: FEBRUARY, 2026 | B21: Underground | C21: JACKFORD L. PALSAAN | D21: 1858 | E21: LHD Optr | F21: Struck by Falling Rock | G21: Stope | H21: 890L | I21: 46076 | J21: 0.85416667 | K21: Third | L21: Venancio A. Bad-ay | M21: Dimas S. Gao-ay | N21: Ryan M. Macaburas | O21: FAC | P21: LHD Mucking Activity | Q21: JAW/SAU | R21: MOG | S21: Dept. 1 | T21: Section 1 | U21: MAT | V21: 2325 6M4 | W21: VAB / DSG / RMM | X21: MOG - 1: Section 1
A22: FEBRUARY, 2026 | B22: Underground | C22: CRAYTON B. CALSIYAO | D22: 9690 | E22: Assistant Miner | F22: Punctured | G22: Stope | H22: 1000L | I22: 46077 | J22: 0.0625 | K22: First | L22: Venancio A. Bad-ay | M22: June O. Golocan | N22: Bernard M. Itliong | O22: FAC | P22: Pulling out Timber Logs | Q22: RWV | R22: MOG | S22: Dept. 1 | T22: Section 3 | U22: MAT | V22: 205 4M4 | W22: VAB / JOG / BMI | X22: MOG - 1: Section 3
A23: FEBRUARY, 2026 | B23: Underground | C23: LEONARD D. SALINGSING | D23: 9820 | E23: Geotech Aide | F23: Struck by Falling Rock | G23: Stope | H23: 880L | I23: 46077 | J23: 0.32291667 | K23: Second | L23: Kurt Linis Ljomir Ursua | M23: Benito A. Islao Jr. | N23: Romy A. Domyong | O23: LTA-NF | P23: Ground Condition & Support Assessment | Q23: AOV/ACB/WLT | R23: MEGG | S23: Min Geology | T23: Rock Mechanics | U23: MAT | V23: 12508 H31N | W23: KLLU / BAIJr. / RAD | X23: MEGG - Rock Mechanics
A24: FEBRUARY, 2026 | B24: Underground | C24: JERRY L. BISTAYOK | D24: 7230 | E24: Assistant Miner | F24: Struck by Falling Rock | G24: Development | H24: 1000L | I24: 46078 | J24: 0.40625 | K24: Second | L24: Hilbert G. Andong | M24: Ruben T. Saliwey | N24: N/A | O24: FAC | P24: Bar down | Q24: AOV/ACB/WLT/EAR/MAT | R24: MOG | S24: Dept. 2 | T24: Section 5 | U24: MAT | V24: 320 XCE | W24: HGA / RTS / - | X24: MOG - 2: Section 5
A25: FEBRUARY, 2026 | B25: Surface | C25: TALIWAN JR., SIMON A. | D25: 790 | E25: Laboratory Technician | F25: Fall on Lower level | G25: Crushing Area | H25: S (N/A) | I25: 46077 | J25: 0.39583333 | K25: Second | L25: John Paul C. Licot | M25: N/A | N25: Marry Joy S. Ronulo | O25: NM | P25: Descending the ramp | Q25: RML / MBK | R25: MPG | S25: Metallurgy | T25: Laboratory | U25: KTA | V25: Gap b/n conveyor and ramp | W25: JPC / - / MJSR | X25: MPG - Metallurgy - Laboratory
A26: FEBRUARY, 2026 | B26: Surface | C26: BURNT GARBAGE | D26: N/A - EI | E26: Forest Fire | F26: Fire | G26: Gravel Pit, Sapid | H26: S (N/A) | I26: 46059 | J26: 0.71180556 | K26: Third | L26: N/A | M26: N/A | N26: N/A | O26: EI | P26: IEC at Brgy. Sapid | Q26: MBK | R26: ASG | S26: IOSD | T26: N/A - Community | U26: KTA | W26: N/A | X26: N/A - Emergency Incident
A27: FEBRUARY, 2026 | B27: Surface | C27: LMD EMPLOYEES | D27: N/A - EI | E27: N/A | F27: Earthquake | G27: Surface LMD Camp | H27: S (N/A) | I27: 46069 | J27: 0.40277778 | K27: Second | L27: N/A | M27: N/A | N27: N/A | O27: EI | P27: Normal Surface Operations | Q27: RML | R27: ASG | S27: IOSD | T27: N/A - Community | U27: KTA | W27: N/A | X27: N/A - Emergency Incident
A28: FEBRUARY, 2026 | B28: Surface | C28: PINE TREES | D28: N/A - EI | E28: Forest Fire | F28: Fire | G28: Golf Course, Sapid | H28: S (N/A) | I28: 46074 | J28: 0.69791667 | K28: Third | L28: N/A | M28: N/A | N28: N/A | O28: EI | P28: Normal Surface Operations | Q28: MBK | R28: ASG | S28: IOSD | T28: N/A - Community | U28: KTA | W28: N/A | X28: N/A - Emergency Incident
A29: FEBRUARY, 2026 | B29: Surface | C29: PINE TREES | D29: N/A - EI | E29: Forest Fire | F29: Fire | G29: Tagumbao, Sapid | H29: S (N/A) | I29: February 26, 2026 | J29: 0.85763889 | K29: Third | L29: N/A | M29: N/A | N29: N/A | O29: EI | P29: Normal Surface Operations | Q29: ACG | R29: ASG | S29: IOSD | T29: N/A - Community | U29: KTA | W29: N/A | X29: N/A - Emergency Incident
A30: FEBRUARY, 2026 | B30: Surface | C30: HOSE | D30: N/A - EI | E30: Forest Fire | F30: Fire | G30: Aerodome Area | H30: S (N/A) | I30: February 28, 2026 | J30: 0.48888889 | K30: Second | L30: N/A | M30: N/A | N30: N/A | O30: EI | P30: Normal Surface Operations | Q30: RML | R30: ASG | S30: IOSD | T30: N/A - Community | U30: KTA | W30: N/A | X30: N/A - Emergency Incident
A31: MARCH, 2026 | B31: Surface | C31: FOREST FIRE | D31: N/A - EI | E31: Forest Fire | F31: Fire | G31: Golf Course, Sapid | H31: S (N/A) | I31: March 6, 2026 | J31: 0.91041667 | K31: Third | L31: N/A | M31: N/A | N31: N/A | O31: EI | P31: Burning of dry grass | Q31: ENC | R31: ASG | S31: IOSD | T31: N/A - Community | U31: KTA | W31: N/A | X31: N/A - Emergency Incident | Y31: N/A | Z31: N/A | AA31: N/A
A32: MARCH, 2026 | B32: Surface | C32: OIL SPILL | D32: TFQ 524 | E32: Mill Engineering Service Vehicle | F32: Property Damage | G32: LMD Roadway | H32: S (N/A) | I32: March 9, 2026 | J32: 0.40208333 | K32: Second | L32: Abraham L. Davis | M32: Julius K. Finatec | N32: N/A | O32: EI | P32: Whilst backing: Parking inside GO | Q32: MBK / RML | R32: MPG | S32: Mill Engineering | U32: KTA | V32: General Office Area | W32: ALD / JKF / - | X32: MPG - Mill Engineering | Y32: N/A | Z32: N/A | AA32: N/A
A33: MARCH, 2026 | B33: Surface | C33: LIME SURGE TANK | D33: N/A - PD | E33: Lime Surge Tank | F33: Contact with Object | G33: Lime Plant | H33: S (N/A) | I33: March 14, 2026 | J33: 0.9375 | K33: Third | L33: Dexter B. Arevalo | M33: Jeric T. Dulawan | N33: Lawana Jr., Aquino P. | O33: PD | P33: Normal Surface Operations | Q33: MBK | R33: MPG | S33: Mill Operations | T33: Grinding | U33: KTA | V33: Lime Tank 17/25 | W33: DBA / JTD / APLJr. | X33: MPG - Mill Operations - Crushing & Grinding | Y33: N/A | Z33: N/A | AA33: N/A
A34: MARCH, 2026 | B34: Surface | C34: FOREST FIRE | D34: N/A - EI | E34: Forest Fire | F34: Fire | G34: Slaughter, San Roque | H34: S (N/A) | I34: March 14, 2026 | J34: 0.75 | K34: Third | L34: N/A | M34: N/A | N34: N/A | O34: EI | P34: Burning of dry grass | Q34: MBK | R34: ASG | S34: IOSD | T34: N/A - Community | U34: KTA | W34: N/A | X34: N/A - Emergency Incident | Y34: N/A | Z34: N/A | AA34: N/A
A35: MARCH, 2026 | B35: Surface | C35: FOREST FIRE | D35: N/A - EI | E35: Forest Fire | F35: Fire | G35: Tagumbao, Sapid | H35: S (N/A) | I35: March 14, 2026 | J35: 0.75 | K35: Third | L35: N/A | M35: N/A | N35: N/A | O35: EI | P35: Burning of Garbage | Q35: MBK | R35: ASG | S35: IOSD | T35: N/A - Community | U35: KTA | W35: N/A | X35: N/A - Emergency Incident | Y35: N/A | Z35: N/A | AA35: N/A
A36: MARCH, 2026 | B36: Underground | C36: JUN JUN G. DAGYO | D36: 9923 | E36: Assistant Miner | F36: Occupational Illness / Pain | G36: Stope | H36: 870L | I36: March 9, 2026 | J36: 0.45833333 | K36: Second | L36: Venancio A. Bad-ay | M36: Dimas S. Gao-ay | N36: Ryan M. Macaburas | O36: OI | P36: Hand Mucking | Q36: MAT/WDL/RWV | R36: MOG | S36: Dept. 1 | T36: Section 1 | U36: MAT | V36: 225 6L1 | W36: VAB / DSG / RMM | X36: MOG - 1: Section 1 | Y36: T/C Electrolyte Imbalance | Z36: IVF Hydration | AA36: Fit to Work
A37: MARCH, 2026 | B37: Underground | C37: NESTOR O. DUGAO | D37: 9771 | E37: Geologic Sampler | F37: Contact with Smoke | G37: Mainline / Access | H37: 870L | I37: 46092 | J37: 0.38194444 | K37: Second | L37: Kurt Linis Ljomir Ursua | M37: Bullet P. Tangcalagan | N37: Sandro Daniel G. Cababa | O37: OI | P37: Waiting for the LHD mucking activity | Q37: AOV/WLT/EAR/MAT | R37: MEGG | S37: Mine Geology | T37: Mine Geology Operations | U37: KTA | V37: 256 RB Access | W37: KLLU / BPT / SDGC | X37: MEGG - Mine Geology | Y37: Smoke Inhalation Injury | Z37: Admission | AA37: For further Medical Evaluation: For in-patient management
A38: MARCH, 2026 | B38: Underground | C38: JOMEL W. DAWING | D38: 9697 | E38: Maintenance Man (MMME) | F38: Struck by Object | G38: Rock Drill Shop | H38: 1000L | I38: 46095 | J38: 0.33333333 | K38: Third | L38: Fernando A. Bustillo Jr. | M38: Baker S. Calbid | N38: N/A | O38: FAC | P38: In the process of knocking out the control valve assembly of RDM #22013 | Q38: SAU | R38: MOG | S38: MMME | T38: Non-Mobile | U38: MAT | V38: 249 Rock Drill Shop | W38: FABJr. / BSC / - | X38: MOG - MMME - Non-Mobile | Y38: Superficial Avulsed Wound, 3rd Digit Left Hand | Z38: Xray of Left Hand, Anti-Tetanous Vaccine, Antibiotics, Analgesic | AA38: Fit to Work
A39: MARCH, 2026 | B39: Underground | C39: ALBERT M. ALIGA | D39: 9946 | E39: Assistant Miner | F39: Struck by Falling Rock | G39: Development | H39: 1000L | I39: 46097 | J39: 0.15625 | K39: First | L39: Hilbert G. Andong | M39: Ruben T. Saliwey | N39: Andy M. Delumen | O39: FAC | P39: Cleaning of Blast Hole through blow piping | Q39: WDL/RWV | R39: MOG | S39: Dept. 2 | T39: Section 5 | U39: MAT | V39: 320 XCE | W39: HGA / RTS / AMD | X39: MOG - 2: Section 5 | Y39: Multiple Lacerated Wound on Forehead | Z39: Wound Suturing | AA39: Fit to Work
A40: MARCH, 2026 | B40: Underground | C40: REYMARK L. LANGOEY | D40: 1930 | E40: Shaftman | F40: Occupational Illness / Pain | G40: Shaft Station / Resting Area | H40: S (N/A) | I40: 46098 | J40: 0.5625 | K40: Second | L40: Jayson T. Capia-ao | M40: Edie S. Pacsay | N40: Angelito A. Delim | O40: OI | P40: Changing his working clothes | Q40: MAT/WLT | R40: MOG | S40: GMS | T40: Tubo Shaft Operation / 670L Pumping | U40: KTA | V40: Change Room, Tubo | W40: JTC / ESP / AAD | X40: MOG - GMS - Tubo Shaft | Y40: Acute Gastritis | Z40: Admitted for IV Hydration and Medication | AA40: Fit to Work
...

Sheet Description of Incidents
A1: Brief Description of Incident (s): | B1: 46023
A2: =input!$C$2 -> RYAN DAVE MAWI-IT | B2: Janauary 10, 2026: The victim, together with his companions, was assigned to clean the canal along the drift at the RP. 22 Area. After completing the activity, he took a bath and suddenly felt chills accompanied by shivering. As a result, his on-shift supervisor, Reynaldo P. Kiking, advised him to rest at eating station and immediately called an ambulance for medical check up.
A3: OI
A4: RP NO.22 900L
A5: =input!$C$3 -> JOEY A. LASSIN | B5: January 16, 2026: At approximately 11:00 AM, Messrs. Ladwingon and the victim were assigned to 21516 4M4. Their supervisor, Engr. Fawayan, instructed them to conduct barring down and update ground support (rock bolting) after noticing a five-meter backlog in rock bolting from the previous shift. Messrs. Ladwingon and Lassin began their work, performing barring down and reinstalling the disturbed stull caused by the previous shift’s blasting activity. While conducting the rock bolting operation, the victim was collaring the 18th hole when a loose rock unexpectedly fell from behind, resulting in an abrasion injury to his back.Immediately after the incident, Mr. Ladwingon sought assistance from a nearby LHD operator and reported the injury to their supervisor.
A6: FAC
A7: 21516 4M4, 970L
A8: =input!$C$4 -> MANUEL D. BALAIS | B8: Janauary 24, 2026: The victim did his routine in all working areas, at arround 3:00 am. He returned at 305 Ramp to double check his crew working thereat. The crew were eating their snack so the victim continued breaking the uneven roadway using the breaker. On the process, the air nozzle of the breaker flashes to the ground and a particle hit the left eye of the victim.
A9: FAC
A10: 305 RAMP, 1100L
A11: =input!$C$5 -> WILBUR D. AWIS | B11: Janauary 25, 2026: The victim was at the eating station while preparing to conduct his work when he suddenly felt dizzy. Later on, it was found out that the victim forgot to take his maintenance medicine.
A12: OI
A13: RP NO.22 900L
A14: =input!$C$6 -> DUMAGUING M. LIBAN | B14: On January 26, 2026, LHD operator Mr. Liban descended to the ramp after conducting scraping from the upper elevation. During his descent, a crew noticed him approaching them who were conducting timbering in a section of the Ramp. At approximately 07:30 PM, Mr. Liban engaged the park brake of his loader and subsequently alighted to engage the shut-off valve engine. The loader suddenly moved in a free wheeled and downward the ramp towards the crew timbering crew so he immediately warned the crew nearby. Apparently, he attempted to re- ride in his unit to stop. The crew fled from the area upon hearing the warning of Mr. Liban, few moments later, they already found him unresponsive, lying on his left side and his head was positioned almost underneath of the stepping board of the unit. Rescuers extricated him and was brought to hospital where he already lifeless.
A15: LTA-F
A16: 207 K Ramp, 1012 Elevation, 1000L
A17: =input!$C$7 -> GLENN MARK B. LABOTAN | B17: On January 30, 2026, at approximately 9:45 AM, Messrs. M. Caligner, A. Molano, and A. De Leon were engaged in storing fuel oil drum at the C30 Fuel Storage Area, Mr. Labotan observed the activity and voluntarily offered his assistance. During unloading, the drum was initailly placed in a resting position and subsequently rolled inside the storage area for proper placement. While Mr. Caligner and Mr. labotan were lifting the drum to its rack, the drum suddenly shifted due to its weight. Mr. Labotan was unable to withdraw his hand in time resulting in his fingers being caught in a pich point and sustaining injury. The injured employee was immediately transported to the 1150L shaft station and subsequently conveyed by ambulance to the company hospital for further treatment.
A18: LTA-NF
A19: C30 Fuel Storage
A20: =input!$C$8 -> BINSON I. ZAPARITA | B20: The material of ball mill #1 pinion shaft was already cut off at the power saw. The supervisor of the victim instructed him to assist in unloading the excess material from the machine. The victim measured the center of the shaft and placed the rope. His companion operates the crane while he and his other coworker are supporting at each end of the shaft. The lifting of the material was unbalanced on their first attempt so they adjusted the rope. They lifted the shaft but unfortunately the rope swung which resulted in the injury of the victim. The right ring finger of the victim was caught in between the shaft and the clamping vise.
A21: =input!O8 -> FAC
A22: Machine Shop
A23: =input!C9 -> ROWELL C. DELA CRUZ | B23: Around 7:45 AM of January 12, 2026 the victim and his companions are loading caustic sodas in the steelyard to be delivered at CIP. As they were lifting the caustic sodas, a bunch of sacks tipped over. The victim together with his workmate repiled the bags of caustic sodas. The victim did not realized that a small portion of caustic sodas was spilled into his left shoe. At around past 8:00 AM they delivered the caustic sodas to CIP and returned at the steelyard approximately 9:00 AM. The victim felt stingy on his left foot and reported to his supervisor. He was admitted at the hospital 10:02 AM.
A24: =input!O9 -> FAC
A25: Steel Yard
A26: =input!C10 -> JOHN REY BAGUIYAC | B26: The victim together with his companions were deployed and assigned to repair termite-infested columns and beams at the proposed hemodialysis station of the hospital. The existing columns and beams were scheduled to be replaced with 6x6 H-beams to stabilize area. The crew was instructed that all cutting of H-beams should be performed outside the hospital premises. Due to the large number of hospital clients at the time, the crew decided to haul the H-beams inside the area. During the lowering of the H-beam while counting and coordinating the movement, the victim was delayed in pulling his hand resulting in his hand being caught in between the beam.
A27: =input!O10 -> FAC
A28: =input!V10 -> Proposed Hemodialysis Station
A29: =input!C11 -> FUSE CUT-OFF SWITCH | B29: There was a sudden power loss from the 220V transformer. Control group was called since the jaw crusher was not able to perform with the power loss. Upon inspection the team noticed that the fuse cut-off switch was sparking and producing smoke. The workers quenched the spark with fire extinguisher.
A30: =input!O11 -> PD
A31: =input!V11 -> 300 KVA Substation
A32: =input!C12 -> PINE TREES | B32: January 21, 2026: Buaki, Sapid: Around 4:00 PM, GO Guard received a phone call from Buaki Guard regarding an ongoing fire incident located at Buaki Area. They noticed that the fire was spreading so responders borded the firetruck and proceeded to the area. Upon arrival at 4:14PM, VSAI responders, along with the community began to suppress the fire by allowing them to utilize their water hoses, while safety responders on site were in charge of safety measures. After inspection, at least 25 grown pine trees were partially burnt in the 450 square meter of affected area. Witnesses from the community stated that they saw two (2) minor children roaming the affected area before the fire occured. No one identified the minors but they were advised to submit the names once found out. Fire-out was declared at 5:27 PM. Debriefing was headed by Mr. Alfe C. Guaki.
A33: =input!O12 -> EI
A34: =input!G12 -> Buaki, Sapid
A35: =input!C13 -> BURNT GARBAGE | B35: January 24, 2026, Golf Course, Sapid: GO Guard on duty received a phone call relayed by the Gate 3 guard regarding an onhoing fire at Golf Course, Sapid noticed by a Mr. Bustillo when he was passing through at the area. The powerhouse wa notified to sound the alarm. Other concerned departments were also notified. Responders arrived at 7:46 PM, who saw that the fire was on its dying-out stage as the onsite VSAI personnel used tree branches to suppress the fire. For certainty, the firetruck was used to thoroughly sweep burning ashes and smoky portions. Clearing and investigations was conducted after: at least 30 square meters was burnt and no damages was found. Fire our was announced at about 8:10PM followed by debriefing headed by Engr. Alfe C. Guaki.
A36: =input!O13 -> EI
A37: =input!G13 -> Golf Course, Sapid
A38: =input!C14 -> VOLVO TRUCK | B38: January 30, 2026: 6:54 AM: Shipside-operated delivery truck / hauler, was assigned to transport materials from Bulacan. Skid marks indicated that the truck lost traction on the right side, swung left and struck the parapet. The driver stated that whiledescending a curved section of Upper Golf Course Rd., he observed an oncoming SUV travelling upheil. To yield the right of way, he steered the truck toward the right side of the road. However, the trucks' right-side wheel inadvertently entered a roadside canal approcimately two feet deep. In an effort to recover the vehicles and turn it to the roadway, he steered left, briefly accelerated, and then applied the breaks. unfortunately the brakes failed to function. Due to the vehicles' weight ant the slippery conditions caused by muddy soil and wet pine needles along the roadside, the ruck lost traction, skidded forward, and ultimately slid into the ditch on the left side of the roadway. The truck was found at the bottom of a ravine, sustaining extensive damage which scattered 10 sacks of Sodium metabisulphite (SMBS) around the site, resulting in a solid chemical spill, which were transferred into new sacks for safetkeeping before the materials were delivered to the Mill Detox Area. The driver and his companion was immediately transported to the LMD Hospital for medical assessment and treatment. The driver sustained a laceration on the right hand, fifth digit and back pain, while the passenger suffered a right infraorbital contusion with hematoma. The truck was recovered at around 11:00 PM using Loaders deployed by LMD and was temporarily parked at Mr. Negradas' plce in Tubo. As of the written report, the vehicle remains there pending a complete assessment by Shipside Maintenance.
A39: =input!O14 -> EI
A40: =input!G14 -> Tubo, Sapid
...

Sheet January
B1: ACCIDENT MONITORING REPORT
B2: JANUARY, 2026
B3: Name of Person Injured / Damaged Property | D3: CN / Unit # | E3: Occupation / Designation | F3: Type of Incident | H3: Work Place / Area | I3: Level | J3: Date | L3: Time | N3: Shift | O3: Dep't Head | P3: Section Head | Q3: Immediate Supervisor | R3: Nature of Injury | S3: On-Going Activity | T3: Safety Inspector On-duty | V3: Group | W3: Department | Y3: Section | Z3: Recorded By
B5: UNDERGROUND:
B6: =input!C2 -> RYAN DAVE MAWI-IT | D6: =input!D2 -> 8471 | E6: =input!E2 -> Assistant Miner | F6: =input!F2 -> Occupational Illness / Pain | H6: =input!G2 -> Shaft Station / Resting Area | I6: =input!H2 -> 900L | J6: =input!I2 -> 46032 | L6: =input!J2 -> 0.97916667 | N6: =input!K2 -> Second | O6: =input!L2 -> Hilbert G. Andong | P6: =input!M2 -> Reynaldo P. Kiking | Q6: =input!N2 -> Stephen Adams D. Mamanteo | R6: =input!O2 -> OI | S6: =input!P2 -> Cleaning of canal. | T6: =input!Q2 -> WDL / MAT | V6: =input!R2 -> MOG | W6: =input!S2 -> Dept. 2 | Y6: =input!T2 -> Section 6 | Z6: =input!U2 -> MAT
B7: =input!C3 -> JOEY A. LASSIN | D7: =input!D3 -> 9728 | E7: =input!E3 -> Assistant Miner | F7: =input!F3 -> Struck by Falling Rock | H7: =input!G3 -> Stope | I7: =input!H3 -> 970L | J7: =input!I3 -> 46038 | L7: =input!J3 -> 0.97916667 | N7: =input!K3 -> Second | O7: =input!L3 -> Venancio A. Bad-ay | P7: =input!M3 -> Mariel T. Ayong | Q7: =input!N3 -> Leonard K. Fawayan | R7: =input!O3 -> FAC | S7: =input!P3 -> Rock Bolting | T7: =input!Q3 -> JAW / EAR / MAT / AOV | V7: =input!R3 -> MOG | W7: =input!S3 -> Dept. 1 | Y7: =input!T3 -> Section 2 | Z7: =input!U3 -> MAT
B8: =input!C4 -> MANUEL D. BALAIS | D8: =input!D4 -> 1209 | E8: =input!E4 -> Shiftboss | F8: =input!F4 -> Foreign Object in the Eye/s | H8: =input!G4 -> Ramp | I8: =input!H4 -> 1100L | J8: =input!I4 -> 46046 | L8: =input!J4 -> 0.125 | N8: =input!K4 -> First | O8: =input!L4 -> Hilbert G. Andong | P8: =input!M4 -> Allab B. Lal-wet | Q8: =input!N4 -> Dummory Joseff Febrei O. Estepa | R8: =input!O4 -> FAC | S8: =input!P4 -> Operating the breaker | T8: =input!Q4 -> WLT / SUU / FPP | V8: =input!R4 -> MOG | W8: =input!S4 -> Dept. 2 | Y8: =input!T4 -> Section 4 | Z8: =input!U4 -> MAT
B9: =input!C5 -> WILBUR D. AWIS | D9: =input!D5 -> 9940 | E9: =input!E5 -> Maintenance Man (MMME) | F9: =input!F5 -> Occupational Illness / Pain | H9: =input!G5 -> Shaft Station / Resting Area | I9: =input!H5 -> 900L | J9: =input!I5 -> 46047 | L9: =input!J5 -> 0.29166667 | N9: =input!K5 -> Second | O9: =input!L5 -> Fernando A. Bustillo Jr. | P9: =input!M5 -> Alfon B. Yodong | Q9: =input!N5 -> John Pauline M. Refugia | R9: =input!O5 -> OI | S9: =input!P5 -> Preparing for task | T9: =input!Q5 -> SUU | V9: =input!R5 -> MOG | W9: =input!S5 -> MMME | Y9: =input!T5 -> Mobile | Z9: =input!U5 -> MAT
B10: =input!C6 -> DUMAGUING M. LIBAN | D10: =input!D6 -> 1336 | E10: =input!E6 -> LHD Optr | F10: =input!F6 -> Caught in Between | H10: =input!G6 -> Ramp | I10: =input!H6 -> 1000L | J10: =input!I6 -> 46048 | L10: =input!J6 -> 0.8125 | N10: =input!K6 -> Third | O10: =input!L6 -> Venancio A. Bad-ay | P10: =input!M6 -> June O. Golocan | Q10: =input!N6 -> Danilo M. Galande | R10: =input!O6 -> LTA-F | S10: =input!P6 -> Descending towards 900L | T10: =input!Q6 -> WLT / EAR | V10: =input!R6 -> MOG | W10: =input!S6 -> Dept. 1 | Y10: =input!T6 -> Section 3 | Z10: =input!U6 -> MAT
B11: =input!C7 -> GLENN MARK B. LABOTAN | D11: =input!D7 -> 9346 | E11: =input!E7 -> UG Senior Warehouseman | F11: =input!F7 -> Caught in Between | H11: =input!G7 -> Fuel Storage Area | I11: =input!H7 -> 900L | J11: =input!I7 -> 46052 | L11: =input!J7 -> 0.40625 | N11: =input!K7 -> Second | O11: =input!L7 -> Fe Marie W. Mates | P11: =input!M7 -> Samson A. Fotyong | Q11: =input!N7 -> Marvin B. Caligner | R11: =input!O7 -> LTA-NF | S11: =input!P7 -> Unloading fuel oil drum | T11: =input!Q7 -> MAT / AOV | V11: =input!R7 -> FSG | W11: =input!S7 -> IMD | Y11: =input!T7 -> Underground Warehouse | Z11: =input!U7 -> KTA
B12: SURFACE:
